Workbook

Sheet Table of Contents
A1: Page | B1: Table Name
A2: 1 | B2: Craft Historical Data (1971-2024)
A3: 2 | B3: Category Change Per Brewer
A4: 3 | B4: Craft Control Group Data
A5: 4 | B5: Large Brewer Regionals (Brands not in data set)
A6: 5 | B6: State Production (Craft, 2011-2024)
A7: 6 | B7: Breweries by State
A8: 7 | B8: 21+ Population Data
A9: 8 | B9: TTB State Permit Data (2000-2024)
A10: 9 | B10: Do Not Publish Brewery List
A12: Thanks for being a Brewers Association member!

Sheet 1. Craft Historical
A1: Craft Barrels* | B1: 2024 | C1: 2023 | D1: 2022 | E1: 2021 | F1: 2020 | G1: 2019 | H1: 2018 | I1: 2017 | J1: 2016 | K1: 2015 | L1: 2014 | M1: 2013 | N1: 2012 | O1: 2011 | P1: 2010 | Q1: 2009 | R1: 2008 | S1: 2007 | T1: 2006 | U1: 2005 | V1: 2004 | W1: 2003 | X1: 2002 | Y1: 2001 | Z1: 2000 | AA1: 1999 | AB1: 1998 | AC1: 1997 | AD1: 1996 | AE1: 1995 | AF1: 1994 | AG1: 1993 | AH1: 1992 | AI1: 1991 | AJ1: 1990 | AK1: 1989 | AL1: 1988 | AM1: 1987 | AN1: 1986 | AO1: 1985 | AP1: 1984 | AQ1: 1983 | AR1: 1982 | AS1: 1981 | AT1: 1980 | AU1: 1979 | AV1: 1978 | AW1: 1977 | AX1: 1976 | AY1: 1975 | AZ1: 1974 | BA1: 1973 | BB1: 1972 | BC1: 1971
A2: Contract | B2: 342946.39 | C2: 197194.59 | D2: 228440 | E2: 228440 | F2: 324524 | G2: 309301 | H2: 287402 | I2: 258197 | J2: 244214 | K2: 210362 | L2: 257517 | M2: 176210 | N2: 222702 | O2: 182278 | P2: 230636 | Q2: 282004 | R2: 1252232 | S2: 1380738 | T2: 1132807 | U2: 854155 | V2: 747564 | W2: 838165 | X2: 970802 | Y2: 1024278 | Z2: 1364489 | AA2: 1404472 | AB2: 1781508 | AC2: 1853020 | AD2: 1955939 | AE2: 1579495 | AF2: 1060966 | AG2: 675294 | AH2: 437181 | AI2: 295849 | AJ2: 203383 | AK2: 152689 | AL2: 92442 | AM2: 58606 | AN2: 28918 | AO2: 9000 | AP2: 10120 | AQ2: 6660 | AR2: 3150 | AS2: 1700
A3: Regional | B3: 15547863 | C3: 15352323 | D3: 16539816 | E3: 16539816 | F3: 15425589 | G3: 17739809 | H3: 17751883 | I3: 17744740 | J3: 17883085 | K3: 18841448 | L3: 17412333 | M3: 11973628 | N3: 10237632 | O3: 9041364 | P3: 8034796 | Q3: 7129471 | R3: 5627520 | S3: 4909595 | T3: 4419523 | U3: 4059412 | V3: 3750887 | W3: 3424750 | X3: 3102622 | Y3: 2914527 | Z3: 2474266 | AA3: 2396667 | AB3: 1904237 | AC3: 1605447 | AD3: 1579290 | AE3: 1264177 | AF3: 640703 | AG3: 431030 | AH3: 275173 | AI3: 188700 | AJ3: 122000 | AK3: 94484 | AL3: 53000 | AM3: 47400 | AN3: 41777 | AO3: 38380 | AP3: 37681 | AQ3: 36760 | AR3: 29100 | AS3: 29910 | AT3: 24220
A4: Microbrewery | B4: 3794856.5 | C4: 4190213 | D4: 4465081 | E4: 4465081 | F4: 4113685 | G4: 4915195 | H4: 5913143 | I4: 5508641 | J4: 4865341 | K4: 3946399 | L4: 3161365 | M4: 2377107 | N4: 1905212 | O4: 1432034 | P4: 1141118 | Q4: 947851 | R4: 906955 | S4: 968736 | T4: 846807 | U4: 708014 | V4: 700768 | W4: 666564 | X4: 735120 | Y4: 749053 | Z4: 783153 | AA4: 788488 | AB4: 775672 | AC4: 760222 | AD4: 708743 | AE4: 595495 | AF4: 455853 | AG4: 362240 | AH4: 330114 | AI4: 257634 | AJ4: 220780 | AK4: 182582 | AL4: 137029 | AM4: 103422 | AN4: 48410 | AO4: 26407 | AP4: 13779 | AQ4: 8650 | AR4: 4600 | AS4: 3050 | AT4: 2250 | AU4: 12980 | AV4: 12720 | AW4: 10450 | AX4: 7860 | AY4: 7400 | AZ4: 6190 | BA4: 4730 | BB4: 3780 | BC4: 2030
A5: Taproom | B5: 1917107.7 | C5: 1951365.9 | D5: 1932539 | E5: 1932539 | F5: 1664315 | G5: 1676346
A6: Brewpub | B6: 1518367.7 | C6: 1668773.8 | D6: 1580950 | E6: 1580950 | F6: 1310071 | G6: 1679130 | H6: 1505001 | I6: 1446982 | J6: 1309909 | K6: 1184252 | L6: 1167164 | M6: 977905 | N6: 870371 | O6: 811661 | P6: 727427 | Q6: 705303 | R6: 696952 | S6: 718734 | T6: 699554 | U6: 672219 | V6: 633463 | W6: 602962 | X6: 652608 | Y6: 665132 | Z6: 685559 | AA6: 680818 | AB6: 686693 | AC6: 678145 | AD6: 548029 | AE6: 377569 | AF6: 257677 | AG6: 201418 | AH6: 146792 | AI6: 112154 | AJ6: 88726 | AK6: 61639 | AL6: 33589 | AM6: 11113 | AN6: 7803 | AO6: 1473 | AP6: 2000
A8: Total Craft Barrels | B8: =SUM(B2:B6) -> 23121141 | C8: =SUM(C2:C6) -> 23359870 | D8: 24273285 | E8: 24746823 | F8: 22838183 | G8: 26319781 | H8: 25457429 | I8: 24958560 | J8: 24302549 | K8: 24182461 | L8: 21998379 | M8: 15504850 | N8: 13235917 | O8: 11467337 | P8: 10133977 | Q8: 9064629 | R8: 8483659 | S8: 7977803 | T8: 7098691 | U8: 6293800 | V8: 5832682 | W8: 5532441 | X8: 5461152 | Y8: 5352990 | Z8: 5307467 | AA8: 5270445 | AB8: 5148110 | AC8: 4896834 | AD8: 4792001 | AE8: 3816736 | AF8: 2415199 | AG8: 1669982 | AH8: 1189260 | AI8: 854337 | AJ8: 634889 | AK8: 491394 | AL8: 316060 | AM8: 220541 | AN8: 126908 | AO8: 75260 | AP8: 63580 | AQ8: 52070 | AR8: 36850 | AS8: 34660 | AT8: 26470 | AU8: 12980 | AV8: 12720 | AW8: 10450 | AX8: 7860 | AY8: 7400 | AZ8: 6190 | BA8: 4730 | BB8: 3780 | BC8: 2030
A10: Data set Change | B10: +706,734 to base | C10: -677,201 from base | D10: -490,000 from base | E10: +95,000 to base | F10: -912,166 from base | G10: -27,000 from base | H10: -160,945 from base | I10: -303,143 from base | J10: - 1,235,463 from base | K10: - 438,276 from base | L10: + 3,166,223 to base
A11: Barrel Change (Comparable) | B11: =B8-(C8+706734) -> -945462.74 | C11: -236213.86 | D11: =D8-(E8-490000) -> 16462 | E11: =E8-95000-F8 -> 1813640 | F11: -2569432 | G11: 889352 | H11: 659814 | I11: 959154 | J11: 1355551.4 | K11: 2461409 | L11: 3327306 | M11: 2268933 | N11: 1768580 | O11: 1333360 | P11: 1069348 | Q11: 580970 | R11: 505856 | S11: 879112 | T11: 804891 | U11: 461118 | V11: 300241 | W11: 71289 | X11: 108162 | Y11: 45523 | Z11: 37022 | AA11: 122335 | AB11: 251276 | AC11: 104833 | AD11: 975265 | AE11: 1401537 | AF11: 745217 | AG11: 480722 | AH11: 334923 | AI11: 219448 | AJ11: 143495 | AK11: 175334 | AL11: 95519 | AM11: 93633 | AN11: 51648 | AO11: 11680 | AP11: 11510 | AQ11: 15220 | AR11: 2190 | AS11: 8190 | AT11: 13490 | AU11: 260 | AV11: 2270 | AW11: 2590 | AX11: 460 | AY11: 1210 | AZ11: 1460 | BA11: 950 | BB11: 1750 | BC11: 770
A13: Percent Volume Growth (Comparable) | B13: =-0.039299642059192*100 -> -3.9299642 | C13: =-0.00973143355435669*100 -> -0.97314336 | D13: 0.07 | E13: 7.94 | F13: -10.11 | G13: 3.4971962 | H13: 2.6607962 | I13: 3.9965739 | J13: 5.907315 | K13: 11.331905 | L13: 17.8 | M13: 17.1 | N13: 15.4 | O13: 13.2 | P13: 11.8 | Q13: 6.8 | R13: 6.3 | S13: 12.4 | T13: 12.8 | U13: 7.9 | V13: 5.4 | W13: 1.3054819 | X13: 2.0207451 | Y13: 0.85778238 | Z13: 0.70250008 | AA13: 2.3764982 | AB13: 5.1318268 | AC13: 2.1791106 | AD13: 25.552331 | AE13: 58.029877 | AF13: 44.624253 | AG13: 40.421943 | AH13: 39.20268 | AI13: 34.564782 | AJ13: 29.201618 | AK13: 55.47491 | AL13: 43.311221 | AM13: 73.780219 | AN13: 68.626096 | AO13: 18.370557 | AP13: 22.104859 | AQ13: 41.302578 | AR13: 6.3185228 | AS13: 30.940688 | AT13: 103.92912 | AU13: 2.0440252 | AV13: 21.722488 | AW13: 32.951654 | AX13: 6.2162162 | AY13: 19.547658 | AZ13: 30.866808 | BA13: 25.132275 | BB13: 86.206897 | BC13: 61.111111
E14: =E8-F8 -> 1908640
A15: Craft Brewery Count | B15: 2024 | C15: 2023 | D15: 2022 | E15: 2021 | F15: 2020 | G15: 2019 | H15: 2018 | I15: 2017 | J15: 2016 | K15: 2015 | L15: 2014 | M15: 2013 | N15: 2012 | O15: 2011 | P15: 2010 | Q15: 2009 | R15: 2008 | S15: 2007 | T15: 2006 | U15: 2005 | V15: 2004 | W15: 2003 | X15: 2002 | Y15: 2001 | Z15: 2000 | AA15: 1999 | AB15: 1998 | AC15: 1997 | AD15: 1996 | AE15: 1995 | AF15: 1994 | AG15: 1993 | AH15: 1992 | AI15: 1991 | AJ15: 1990 | AK15: 1989 | AL15: 1988 | AM15: 1987 | AN15: 1986 | AO15: 1985 | AP15: 1984 | AQ15: 1983 | AR15: 1982 | AS15: 1981 | AT15: 1980 | AU15: 1979 | AV15: 1978 | AW15: 1977 | AX15: 1976 | AY15: 1975 | AZ15: 1974 | BA15: 1973 | BB15: 1972 | BC15: 1971
A16: Brewpub | B16: 3599 | C16: 3502 | D16: 3418 | E16: 3337 | F16: 3309 | G16: 3171 | H16: 2870 | I16: 2503 | J16: 2208 | K16: 1941 | L16: 1603 | M16: 1348 | N16: 1180 | O16: 1075 | P16: 1057 | Q16: 1022 | R16: 1009 | S16: 982 | T16: 989 | U16: 991 | V16: 1005 | W16: 1011 | X16: 1040 | Y16: 1056 | Z16: 1068 | AA16: 1052 | AB16: 1001 | AC16: 900 | AD16: 693 | AE16: 497 | AF16: 329 | AG16: 237 | AH16: 183 | AI16: 154 | AJ16: 123 | AK16: 107 | AL16: 69 | AM16: 29 | AN16: 16 | AO16: 4 | AP16: 1 | AQ16: 1
A17: Regional | B17: 280 | C17: 257 | D17: 261 | E17: 223 | F17: 220 | G17: 240 | H17: 230 | I17: 202 | J17: 186 | K17: 178 | L17: 135 | M17: 119 | N17: 97 | O17: 88 | P17: 81 | Q17: 71 | R17: 62 | S17: 55 | T17: 50 | U17: 49 | V17: 46 | W17: 43 | X17: 40 | Y17: 39 | Z17: 36 | AA17: 36 | AB17: 32 | AC17: 31 | AD17: 29 | AE17: 24 | AF17: 16 | AG17: 9 | AH17: 6 | AI17: 5 | AJ17: 3 | AK17: 3 | AL17: 1 | AM17: 1 | AN17: 1 | AO17: 1 | AP17: 1 | AQ17: 1 | AR17: 1 | AS17: 1 | AT17: 1
A18: Taproom | B18: 3948 | C18: 3910 | D18: 3838 | E18: 3643 | F18: 3389 | G18: 3091
A19: Microbrewery | B19: 2034 | C19: 2092 | D19: 2035 | E19: 2007 | F19: 2003 | G19: 1917 | H19: 4518 | I19: 3956 | J19: 3319 | K19: 2684 | L19: 2076 | M19: 1510 | N19: 1143 | O19: 813 | P19: 620 | Q19: 507 | R19: 452 | S19: 423 | T19: 370 | U19: 354 | V19: 362 | W19: 376 | X19: 377 | Y19: 392 | Z19: 405 | AA19: 418 | AB19: 420 | AC19: 403 | AD19: 365 | AE19: 273 | AF19: 192 | AG19: 136 | AH19: 106 | AI19: 89 | AJ19: 85 | AK19: 64 | AL19: 54 | AM19: 44 | AN19: 30 | AO19: 27 | AP19: 16 | AQ19: 10 | AR19: 9 | AS19: 7 | AT19: 7 | AU19: 2 | AV19: 2 | AW19: 2 | AX19: 2 | AY19: 1 | AZ19: 1 | BA19: 1 | BB19: 1 | BC19: 1
A21: Total Operating Craft | B21: =B19+B18+B17+B16 -> 9861 | C21: =C19+C18+C17+C16 -> 9761 | D21: =D19+D18+D17+D16 -> 9552 | E21: =E19+E18+E17+E16 -> 9210 | F21: =F19+F18+F17+F16 -> 8921 | G21: =G19+G18+G17+G16 -> 8419 | H21: 7618 | I21: 6661 | J21: 5713 | K21: 4803 | L21: 3814 | M21: 2977 | N21: 2420 | O21: 1976 | P21: 1758 | Q21: 1600 | R21: 1523 | S21: 1460 | T21: 1409 | U21: 1394 | V21: 1413 | W21: 1430 | X21: 1457 | Y21: 1487 | Z21: 1509 | AA21: 1506 | AB21: 1453 | AC21: 1334 | AD21: 1087 | AE21: 794 | AF21: 537 | AG21: 382 | AH21: 295 | AI21: 248 | AJ21: 211 | AK21: 174 | AL21: 124 | AM21: 74 | AN21: 47 | AO21: 32 | AP21: 18 | AQ21: 12 | AR21: 10 | AS21: 8 | AT21: 8 | AU21: 2 | AV21: 2 | AW21: 2 | AX21: 2 | AY21: 1 | AZ21: 1 | BA21: 1 | BB21: 1 | BC21: 1
A23: Average Barrels | B23: 2024 | C23: 2023 | D23: 2021 | E23: 2021 | F23: 2020 | G23: 2019 | H23: 2018 | I23: 2017 | J23: 2016 | K23: 2015 | L23: 2014 | M23: 2013 | N23: 2012 | O23: 2011 | P23: 2010 | Q23: 2009 | R23: 2008 | S23: 2007 | T23: 2006 | U23: 2005 | V23: 2004 | W23: 2003 | X23: 2002 | Y23: 2001 | Z23: 2000 | AA23: 1999 | AB23: 1998 | AC23: 1997 | AD23: 1996 | AE23: 1995 | AF23: 1994 | AG23: 1993 | AH23: 1992 | AI23: 1991 | AJ23: 1990 | AK23: 1989 | AL23: 1988 | AM23: 1987 | AN23: 1986 | AO23: 1985 | AP23: 1984 | AQ23: 1983 | AR23: 1982 | AS23: 1981 | AT23: 1980 | AU23: 1979 | AV23: 1978 | AW23: 1977 | AX23: 1976 | AY23: 1975 | AZ23: 1974 | BA23: 1973 | BB23: 1972 | BC23: 1971
A24: Microbrewery (old definition) | B24: =(B4+B5)/(B18+B19) -> 954.85861 | C24: =(C4+C5)/(C18+C19) -> 1023.2554 | D24: =(D4+D5)/(D18+D19) -> 1089.3274 | E24: =(E4+E5)/(E18+E19) -> 1132.3221 | F24: =(F4+F5)/(F18+F19) -> 1071.5875 | G24: 1295 | H24: 1308.7966 | I24: 1392.4775 | J24: 1465.9057 | K24: 1470.3424 | L24: 1526.492 | M24: 1615.9803 | N24: 1666.8521 | O24: 1761.4194 | P24: 1840.5129 | Q24: 1869.5286 | R24: 2006.5376 | S24: 2290.156 | T24: 2288.6676 | U24: 2000.0395 | V24: 1935.8232 | W24: 1772.7766 | X24: 1949.9204 | Y24: 1910.8495 | Z24: 1933.7111 | AA24: 1886.3349 | AB24: 1846.8381 | AC24: 1886.4069 | AD24: 1941.7616 | AE24: 2181.3004 | AF24: 2374.2344 | AG24: 2663.5294 | AH24: 3114.283 | AI24: 2894.764 | AJ24: 2597.4118 | AK24: 2852.8438 | AL24: 2537.5741 | AM24: 2350.5 | AN24: 1613.6667 | AO24: 978.03704 | AP24: 861.1875 | AQ24: 865 | AR24: 511.11111 | AS24: 435.71429 | AT24: 321.42857 | AU24: 6490 | AV24: 6360 | AW24: 5225 | AX24: 3930 | AY24: 7400 | AZ24: 6190 | BA24: 4730 | BB24: 3780 | BC24: 2030
A25: Microbrewery | B25: =B4/B19 -> 1865.7112 | C25: =C4/C19 -> 2002.9699 | D25: =D4/D19 -> 2194.143 | E25: =E4/E19 -> 2224.7539 | F25: =F4/F19 -> 2053.7619 | G25: 2375
A26: Taproom | B26: =B5/B18 -> 485.58959 | C26: =C5/C18 -> 499.07057 | D26: =D5/D18 -> 503.52762 | E26: =E5/E18 -> 530.4801 | F26: =F5/F18 -> 491.09324 | G26: 530.65717
A27: Brewpub | B27: =B6/B16 -> 421.886 | C27: =C6/C16 -> 476.52022 | D27: =D6/D16 -> 462.53657 | E27: =E6/E16 -> 473.76386 | F27: =F6/F16 -> 395.91145 | G27: 529.52696 | H27: 524.39059 | I27: 578.09908 | J27: 593.25589 | K27: 610.12468 | L27: 728.11229 | M27: 747.63379 | N27: 737.60254 | O27: 755.03349 | P27: 688.19962 | Q27: 690.12035 | R27: 690.73538 | S27: 731.90835 | T27: 707.33468 | U27: 678.32392 | V27: 630.31144 | W27: 596.40158 | X27: 627.50769 | Y27: 629.85985 | Z27: 641.90918 | AA27: 647.1654 | AB27: 686.00699 | AC27: 753.49444 | AD27: 790.80664 | AE27: 759.69618 | AF27: 783.21277 | AG27: 849.86498 | AH27: 802.14208 | AI27: 728.27273 | AJ27: 721.34959 | AK27: 576.06542 | AL27: 486.7971 | AM27: 383.2069 | AN27: 487.6875 | AO27: 368.25 | AP27: 2000
A29: Share data | B29: 2024 | C29: 2023 | D29: 2022 | E29: 2021 | F29: 2020 | G29: 2019 | H29: 2018 | I29: 2017 | J29: 2016 | K29: 2015 | L29: 2014 | M29: 2013 | N29: 2012 | O29: 2011 | P29: 2010 | Q29: 2009 | R29: 2008 | S29: 2007 | T29: 2006 | U29: 2005 | V29: 2004 | W29: 2003 | X29: 2002 | Y29: 2001 | Z29: 2000 | AA29: 1999 | AB29: 1998
A30: Craft Volume Share | B30: 13.288143 | C30: 13.7 | D30: 13.2 | E30: 13 | F30: 12.2 | G30: 13.6 | H30: 13 | I30: 12.5 | J30: 12.1 | K30: 12.2 | L30: 11.05 | M30: 7.76 | N30: 6.52 | O30: 5.73 | P30: 4.97 | Q30: 4.4 | R30: 4.02 | S30: 3.8 | T30: 3.39 | U30: 3.05 | V30: 2.82 | W30: 2.700509 | X30: 2.67 | Y30: 2.6445292 | Z30: 2.6439969 | AA30: 2.6531651 | AB30: 2.6318696
A31: Import | B31: 24.362845 | C31: 23.160797 | D31: 22.2 | E31: 21 | F31: 19.6 | G31: 19 | H31: 18.4 | I31: 17.5 | J31: 16.8 | K31: 15.9 | L31: 14.93 | M31: 13.85 | N31: 13.85 | O31: 13.79 | P31: 13.4 | Q31: 12.62 | R31: 13.65 | S31: 14.2 | T31: 14.042278 | U31: 12.500547 | V31: 11.642134 | W31: 11.580606 | X31: 11.327789 | Y31: 10.815605 | Z31: 10.021871 | AA31: 9.0101293 | AB31: 8.4083623
A32: U.S. Non-Craft | B32: 62.349012 | C32: 63.175928 | D32: 64.5 | E32: 66 | F32: 68.3 | G32: 67.4 | H32: 68.7 | I32: 70 | J32: 71.1 | K32: 71.9 | L32: 74.01 | M32: 78.39 | N32: 79.62 | O32: 80.49 | P32: 81.63 | Q32: 82.98 | R32: 82.33 | S32: 82 | T32: 82.56 | U32: 84.44 | V32: 85.53 | W32: 85.712033 | X32: 86.00729 | Y32: 86.539866 | Z32: 87.334132 | AA32: 88.336706 | AB32: 88.959768
A33: Craft $ Share | B33: 24.674779 | C33: 24.061262 | D33: 24.6 | E33: 25.6 | F33: 23.6 | G33: 25.2 | H33: 24.1 | I33: 22.9 | J33: 21.9 | K33: 21 | L33: 19.32 | M33: 14.28 | N33: 11.94 | O33: 10.6 | P33: 8.7671806 | Q33: 7.5997797 | R33: 7.2962555 | S33: 6.8759912 | T33: 6.1171806 | U33: 5.4400881

Sheet 2. Category Change Per Brewer
A1: Year | B1: Growth Rate (%) | C1: Production Change Barrels | D1: Craft Breweries | E1: Change per Brewer
A2: 2010 | B2: 11.8 | C2: 1069348 | D2: 1758 | E2: 608.27531
A3: 2011 | B3: 13.2 | C3: 1333360 | D3: 1976 | E3: 674.77733
A4: 2012 | B4: 15.4 | C4: 1768580 | D4: 2420 | E4: 730.81818
A5: 2013 | B5: 17.1 | C5: 2268933 | D5: 2977 | E5: 762.15418
A6: 2014 | B6: 17.8 | C6: 3327306 | D6: 3814 | E6: 872.39276
A7: 2015 | B7: 11.331905 | C7: 2461409 | D7: 4803 | E7: 512.47325
A8: 2016 | B8: 5.907315 | C8: 1355551.4 | D8: 5713 | E8: 237.27489
A9: 2017 | B9: 3.9965739 | C9: 959154 | D9: 6661 | E9: 143.9955
A10: 2018 | B10: 2.6607962 | C10: 659814 | D10: 7618 | E10: 86.612497
A11: 2019 | B11: 3.4971962 | C11: 889352 | D11: 8419 | E11: 105.6363
A12: 2020 | B12: -10.1 | C12: -2569432 | D12: 8921 | E12: -288.02063
A13: 2021 | B13: 7.9 | C13: 1813640 | D13: 9210 | E13: 196.92074
A14: 2022 | B14: 0.1 | C14: 16462 | D14: 9552 | E14: =C14/D14 -> 1.7234087
A15: 2023 | B15: ='1. Craft Historical'!C13 -> -0.97314336 | C15: -236214.33 | D15: ='1. Craft Historical'!C21 -> 9761 | E15: =C15/D15 -> -24.199809
A16: 2024 | B16: ='1. Craft Historical'!B13 -> -3.9299642 | C16: -268261.97 | D16: ='1. Craft Historical'!B21 -> 9861 | E16: =C16/D16 -> -27.204337

Sheet 3. Craft Control Group Data
A1: The values listed in this table represent the volume each control group contributed to the craft brewer data set in 2024. Breweries that were "do not publish" are not included (they are in a separate tab), but are included in the aggregated numbers. Some brewery volumes include contract for others (removed in total to avoid double counting).
A2: Control Group | B2: Estimate | C2: City | D2: State | E2: Control Group Production (2024)
A3: D. G. Yuengling and Son Inc | C3: Pottsville | D3: Pennsylvania | E3: 2527500
A4: Boston Beer Co | B4: 1 | C4: Boston | D4: Massachusetts | E4: 1104000
A5: Sierra Nevada Brewing Co | C5: Chico | D5: California | E5: 1065894
A6: Tilray | B6: 1 | C6: New York | D6: New York | E6: 783495
A7: Firestone Walker Brewing Co | B7: 1 | C7: Paso Robles | D7: California | E7: 480000
A8: Gambrinus Company | B8: 1 | C8: San Antonio | D8: Texas | E8: 453859
A9: Saranac Brewery / Matt Brewing Co | C9: Utica | D9: New York | E9: 403367
A10: Athletic Brewing Company | C10: Milford | D10: Connecticut | E10: 399500
A11: Brooklyn Brewery | C11: Brooklyn | D11: New York | E11: 338568
A12: Monster Brewing Company LLC | C12: Longmont | D12: Colorado | E12: 303286
A13: Artisanal Brewing Ventures | C13: Charlotte | D13: North Carolina | E13: 252334
A14: Deschutes Brewery | C14: Bend | D14: Oregon | E14: 248195
A15: New Glarus Brewing Co | C15: New Glarus | D15: Wisconsin | E15: 232171
A16: Duvel Moortgat USA | C16: Kansas City | D16: Missouri | E16: 167000
A17: Barrel One Collective | C17: Boston | D17: Massachusetts | E17: 125400
A18: Georgetown Brewing Co | C18: Seattle | D18: Washington | E18: 122918
A19: Gordon Biersch Brewing Co | B19: 1 | C19: San Jose | D19: California | E19: 122510
A20: Rhinegeist Brewery | C20: Cincinnati | D20: Ohio | E20: 118020
A21: Craft ‘Ohana (Maui/Modern Times) | C21: Kihei | D21: Hawaii | E21: 115645
A22: Great Lakes Brewing Company | C22: Cleveland | D22: Ohio | E22: 114827
A23: Narragansett Brewing Co | C23: Providence | D23: Rhode Island | E23: 111375
A24: Troegs Brewing Co | C24: Hershey | D24: Pennsylvania | E24: 109576
A25: Allagash Brewing Company | C25: Portland | D25: Maine | E25: 109304
A26: August Schell Brewing Company | C26: New Ulm | D26: Minnesota | E26: 108375
A27: Fiddlehead Brewing | C27: Shelburne | D27: Vermont | E27: 108143
A28: Stevens Point Brewery | C28: Stevens Point | D28: Wisconsin | E28: 107000
A29: Pittsburgh Brewing Co | B29: 1 | C29: Creighton | D29: Pennsylvania | E29: 106766
A30: Three Floyds Brewing | C30: Munster | D30: Indiana | E30: 104866
A31: Odell Brewing Co | C31: Fort Collins | D31: Colorado | E31: 98212
A32: Great Frontier Holdings | D32: Oregon | E32: 89460
A33: Abita Brewing Co., L.L.C. | C33: Covington | D33: Louisiana | E33: 89091
A34: BrewDog Brewing Company, LLC | C34: Canal Winchester | D34: Ohio | E34: 89084
A35: Creature Comforts Brewing Co. | C35: Athens | D35: Georgia | E35: 86029
A36: Hendler Family Brewing Company | C36: Framingham | D36: Massachusetts | E36: 86000
A37: Alaskan Brewing Co. | C37: Juneau | D37: Alaska | E37: 82400
A38: Summit Brewing Co | C38: Saint Paul | D38: Minnesota | E38: 76611
A39: Kona Brewing Hawaii | C39: Kailua-Kona | D39: Hawaii | E39: 70081
A40: Saint Arnold Brewing Co | C40: Houston | D40: Texas | E40: 65201
...

Sheet 4. Large Brewer Regionals
A1: Breweries in this table had at least a 25% ownership stake by a large brewing company (>6M barrels globally) by the end of 2024 unless noted otherwise
A3: Company | B3: State | C3: 2020 | D3: 2021 | E3: 2022 | F3: 2023 | G3: 2024 | H3: 2021% | I3: 2022% | J3: 2023% | K3: 2024%
A4: FIFCO USA | B4: NY | C4: 63000 | D4: =D5+D6 -> 29000 | E4: 17000 | F4: =F5+F6 -> 9000 | G4: =G5+G6 -> 8000 | H4: =D4/C4-1 -> -0.53968254 | I4: =E4/D4-1 -> -0.4137931 | J4: =F4/E4-1 -> -0.47058824 | K4: =G4/F4-1 -> -0.11111111
A5: Magic Hat | B5: VT | C5: 30000 | D5: 14000 | E5: 12000 | F5: 7000 | G5: 6000 | H5: =D5/C5-1 -> -0.53333333 | I5: =E5/D5-1 -> -0.14285714 | J5: =F5/E5-1 -> -0.41666667 | K5: =G5/F5-1 -> -0.14285714
A6: Pyramid | B6: WA | C6: 33000 | D6: 15000 | E6: 5000 | F6: 2000 | G6: 2000 | H6: =D6/C6-1 -> -0.54545455 | I6: =E6/D6-1 -> -0.66666667 | J6: =F6/E6-1 -> -0.6 | K6: =G6/F6-1 -> 0
A7: Heineken | C7: 950000 | D7: 900000 | E7: 860000 | F7: 765000 | G7: =G8 -> 706000 | H7: =D7/C7-1 -> -0.052631579 | I7: =E7/D7-1 -> -0.044444444 | J7: =F7/E7-1 -> -0.11046512 | K7: =G7/F7-1 -> -0.077124183
A8: Lagunitas Brewing Co | B8: CA | C8: 950000 | D8: 900000 | E8: 860000 | F8: 765000 | G8: 706000 | H8: =D8/C8-1 -> -0.052631579 | I8: =E8/D8-1 -> -0.044444444 | J8: =F8/E8-1 -> -0.11046512 | K8: =G8/F8-1 -> -0.077124183
A9: Mahou San Miguel | C9: 638750 | D9: =595575 -> 595575 | E9: =E10+E11 -> 501231 | F9: =F10+F11 -> 453502 | G9: =G10+G11 -> 437000 | H9: =D9/C9-1 -> -0.067592955 | I9: =E9/D9-1 -> -0.15840826 | J9: =F9/E9-1 -> -0.09522356 | K9: =G9/F9-1 -> -0.036387932
A10: Founders Brewing Co | B10: MI | C10: 592000 | D10: 540000 | E10: 452787 | F10: 408896 | G10: 400000 | H10: =D10/C10-1 -> -0.087837838 | I10: =E10/D10-1 -> -0.16150556 | J10: =F10/E10-1 -> -0.096935204 | K10: =G10/F10-1 -> -0.021756143
A11: Avery Brewing Co | B11: CO | C11: 48468 | D11: 45575 | E11: 48444 | F11: 44606 | G11: 37000 | H11: =D11/C11-1 -> -0.059688867 | I11: =E11/D11-1 -> 0.062951179 | J11: =F11/E11-1 -> -0.079225497 | K11: =G11/F11-1 -> -0.17051518
A12: Anheuser-Busch | C12: 2731050 | D12: 2720500 | E12: 2625000 | F12: =SUM(F13:F21) -> 1850200 | G12: =SUM(G13:G21) -> 1790000 | H12: =3% -> 0.03 | I12: =E12/D12-1 -> -0.035103841 | J12: =1.9/2.025-1 -> -0.061728395 | K12: =G12/F12-1 -> -0.032537023
A13: Goose Island | B13: IL | C13: 475000 | D13: 465000 | E13: 495000 | F13: 525000 | G13: 508000 | H13: =D13/C13-1 -> -0.021052632 | I13: =E13/D13-1 -> 0.064516129 | J13: =F13/E13-1 -> 0.060606061 | K13: =G13/F13-1 -> -0.032380952
A14: Elysian | B14: WA | C14: 300000 | D14: 330000 | E14: 305000 | F14: 285000 | G14: 262000 | H14: =D14/C14-1 -> 0.1 | I14: =E14/D14-1 -> -0.075757576 | J14: =F14/E14-1 -> -0.06557377 | K14: =G14/F14-1 -> -0.080701754
A15: Four Peaks Brewing Co | B15: AZ | C15: 131250 | D15: 145000 | E15: 140000 | F15: =0.93*E15 -> 130200 | G15: 132000 | H15: =D15/C15-1 -> 0.1047619 | I15: =E15/D15-1 -> -0.034482759 | J15: =F15/E15-1 -> -0.07 | K15: =G15/F15-1 -> 0.013824885
A16: Golden Road Brewing | B16: CA | C16: 240000 | D16: 230000 | E16: 215000 | F16: 195000 | G16: 204000 | H16: =D16/C16-1 -> -0.041666667 | I16: =E16/D16-1 -> -0.065217391 | J16: =F16/E16-1 -> -0.093023256 | K16: =G16/F16-1 -> 0.046153846
A17: Devil's Backbone | B17: VA | C17: 80000 | D17: 85000 | E17: 75000 | F17: 65000 | G17: 50000 | H17: =D17/C17-1 -> 0.0625 | I17: =E17/D17-1 -> -0.11764706 | J17: =F17/E17-1 -> -0.13333333 | K17: =G17/F17-1 -> -0.23076923
A18: Karbach Brewing | B18: TX | C18: 163800 | D18: 176000 | E18: 155000 | F18: 135000 | G18: 116000 | H18: =D18/C18-1 -> 0.074481074 | I18: =E18/D18-1 -> -0.11931818 | J18: =F18/E18-1 -> -0.12903226 | K18: =G18/F18-1 -> -0.14074074
A19: Wicked Weed | B19: NC | C19: 70000 | D19: 97000 | E19: 115000 | F19: 120000 | G19: 126000 | H19: =D19/C19-1 -> 0.38571429 | I19: =E19/D19-1 -> 0.18556701 | J19: =F19/E19-1 -> 0.043478261 | K19: =G19/F19-1 -> 0.05
A20: Platform Brewing Co | B20: OH | C20: 22500 | D20: 22500 | E20: 20000 | F20: 15000 | G20: 6000 | H20: =D20/C20-1 -> 0 | I20: =E20/D20-1 -> -0.11111111 | J20: =F20/E20-1 -> -0.25 | K20: =G20/F20-1 -> -0.6
A21: Kona/Craft Brew Alliance1 | B21: OR | C21: 710000 | D21: 660000 | E21: 640000 | F21: 380000 | G21: 386000 | H21: 0.08 | I21: =E21/D21-1 -> -0.03030303 | J21: =380000/310000-1 -> 0.22580645 | K21: =G21/F21-1 -> 0.015789474
A22: Kirin/Lion Little World Beverages | C22: =C23+C24 -> 1441539.1 | D22: =D23+D24 -> 1570000 | E22: =E23+E24 -> 1675000 | F22: 1850000 | G22: =1864000 -> 1864000 | H22: =D22/C22-1 -> 0.089113697 | I22: =E22/D22-1 -> 0.066878981 | J22: =F22/E22-1 -> 0.10447761 | K22: =G22/F22-1 -> 0.0075675676
A23: New Belgium | B23: CO | C23: 975000 | D23: 1080000 | E23: 1230000 | F23: =F22-F24 -> 1383000 | G23: =G22-G24 -> 1408000 | H23: =D23/C23-1 -> 0.10769231 | I23: =E23/D23-1 -> 0.13888889 | J23: =F23/E23-1 -> 0.12439024 | K23: =G23/F23-1 -> 0.018076645
A24: Bell's Brewing Co | B24: MI | C24: 466539.12 | D24: 490000 | E24: 445000 | F24: 467000 | G24: 456000 | H24: =D24/C24-1 -> 0.050287058 | I24: =E24/D24-1 -> -0.091836735 | J24: =F24/E24-1 -> 0.049438202 | K24: =G24/F24-1 -> -0.023554604
A25: MolsonCoors2 | C25: 2645400 | D25: 2695150 | E25: 2520500 | F25: 2273500 | G25: =SUM(G26:G27) -> 1947000 | H25: =D25/C25-1 -> 0.01880623 | I25: =E25/D25-1 -> -0.064801588 | J25: =F25/E25-1 -> -0.097996429 | K25: =G25/(F25-150000)-1 -> -0.083117495
A26: Blue Moon | B26: National | C26: 1800000 | D26: 1825000 | E26: 1765000 | F26: 1600000 | G26: 1516000 | H26: =D26/C26-1 -> 0.013888889 | I26: =E26/D26-1 -> -0.032876712 | J26: =F26/E26-1 -> -0.093484419 | K26: =G26/F26-1 -> -0.0525
A27: Leinenkugel | B27: WI | C27: 550000 | D27: 575000 | E27: 525000 | F27: 475000 | G27: 431000 | H27: =D27/C27-1 -> 0.045454545 | I27: =E27/D27-1 -> -0.086956522 | J27: =F27/E27-1 -> -0.095238095 | K27: =G27/F27-1 -> -0.092631579
A28: Total3 | C28: =C25+C22+C12+C9+C7+C4 -> 8469739.1 | D28: =D25+D22+D12+D9+D7+D4 -> 8510225 | E28: =E25+E22+E12+E9+E7+E4 -> 8198731 | F28: =F25+F22+F12+F9+F7+F4 -> 7201202 | G28: =G25+G22+G12+G9+G7+G4 -> 6752000 | H28: 0.02 | I28: =E28/D28-1 -> -0.036602323 | J28: =F28/(E28-600000)-1 -> -0.052315183 | K28: =G28/(F28-150000)-1 -> -0.042432765
A29: Breweries in this table had at least a 25% ownership stake by a large brewing company (>6M barrels globally) by the end of 2024 unless noted otherwise.
A30: 1. Anheuser-Busch sold the Widmer and Redhook brands in 2023. They are included in historical estimates but will not be going forward. Starting in 2021, Craft Brew Alliance only includes Kona's mainland volume. The 2021 & 2023 percentage growth numbers are presented on a comparable base and include Kona and Cisco brands.
A31: 2. MolsonCoors sold a number of brands to Tilray in 2024. The percentage growth estimates are presented on a comparable basis for the brands listed below whereas the totals represent owned volume in those years. From 2020-21 includes volume for Saint Archer Brewing brand (not shown).
A32: 3. Growth presented on comparable basis. Does not include volume from brewing companies that were Do Not Publish.

Sheet 5. State Production
A1: Small and Independent Brewery Production by State: 2011 - 2024
A2: Rank | B2: State | D2: 2024 Craft Barrels | E2: 2023 Craft Barrels | F2: 2022 Craft Barrels | G2: 2021 Craft Barrels | H2: 2020 Craft Barrels | I2: 2019 Craft Barrels | J2: 2018 Craft Barrels | K2: 2017 Craft Barrels | L2: 2016 Craft Barrels | M2: 2015 Craft Barrels | N2: 2014 Craft Barrels | O2: 2013 Craft Barrels | P2: 2012 Craft Barrels | Q2: 2011 Craft Barrels | S2: 21+ Population (2024) | T2: Gallons Produced /21+ Adult | U2: Rank
A3: 38 | B3: Alabama | D3: 85970.983 | E3: 90682.661 | F3: 95134.212 | G3: 96004.07 | H3: 78847.03 | I3: 85479.57 | J3: 76639.75 | K3: 62737.74 | L3: 61042.2 | M3: 50369 | N3: 39452 | O3: 32531 | P3: 7274 | Q3: 942 | S3: 3763934 | T3: =(D3*31)/S3 -> 0.70806249 | U3: =RANK(T3,$T$3:$T$53) -> 47
A4: 32 | B4: Alaska | D4: 145808.96 | E4: 152959.94 | F4: 162024.54 | G4: 169661.43 | H4: 161419.55 | I4: 203657.04 | J4: 206939.51 | K4: 204301.88 | L4: 207368.55 | M4: 209644 | N4: 200527 | O4: 182530.38 | P4: 170610 | Q4: 157107 | S4: 533123 | T4: =(D4*31)/S4 -> 8.4784897 | U4: =RANK(T4,$T$3:$T$53) -> 4
A5: 23 | B5: Arizona | D5: 224627.44 | E5: 217731.6 | F5: 219759.95 | G5: 209398.07 | H5: 162402.4 | I5: 204884.64 | J5: 173226.37 | K5: 147727.91 | L5: 147254.55 | M5: 187213 | N5: 156701.54 | O5: 117457.47 | P5: 93103 | Q5: 69080 | S5: 5553078 | T5: =(D5*31)/S5 -> 1.2539803 | U5: =RANK(T5,$T$3:$T$53) -> 36
A6: 44 | B6: Arkansas | D6: 53696.344 | E6: 52809.487 | F6: 52824.32 | G6: 50993.265 | H6: 39990.41 | I6: 46933.76 | J6: 41490.12 | K6: 42294.25 | L6: 35845.69 | M6: 24623 | N6: 14640.75 | O6: 10417 | P6: 5639 | Q6: 4079 | S6: 2243142 | T6: =(D6*31)/S6 -> 0.74207815 | U6: =RANK(T6,$T$3:$T$53) -> 46
A7: 1 | B7: California | D7: 3737147.3 | E7: 3245189.2 | F7: 3237825.3 | G7: 3563691.2 | H7: 3262612.1 | I7: 3785497.3 | J7: 3477216.8 | K7: 3285525 | L7: 3295221.5 | M7: 3799785 | N7: 3423123.9 | O7: 2948894.8 | P7: 2453793 | Q7: 2020246 | S7: 28988643 | T7: =(D7*31)/S7 -> 3.9964467 | U7: =RANK(T7,$T$3:$T$53) -> 14
A8: 9 | B8: Colorado | D8: 779337.77 | E8: 793101.55 | F8: 846323.59 | G8: 846120.53 | H8: 920104.42 | I8: 1555812.8 | J8: 1508824.9 | K8: 1523204.3 | L8: 1429130.5 | M8: 1775831 | N8: 1673686.3 | O8: 1413241.8 | P8: 1291771 | Q8: 1185354 | S8: 4441305 | T8: =(D8*31)/S8 -> 5.4397235 | U8: =RANK(T8,$T$3:$T$53) -> 8
A9: 14 | B9: Connecticut | D9: 428217.66 | E9: 347327.41 | F9: 299158.95 | G9: 291085.47 | H9: 255265.43 | I9: 228981.28 | J9: 209878.85 | K9: 166847.78 | L9: 129824.75 | M9: 105484 | N9: 72682 | O9: 51457 | P9: 40947 | Q9: 23372 | S9: 2743788 | T9: =(D9*31)/S9 -> 4.8381098 | U9: =RANK(T9,$T$3:$T$53) -> 12
A10: 24 | B10: Delaware | D10: 204745.62 | E10: 227265.85 | F10: 236714.56 | G10: 299977.75 | H10: 291481.26 | I10: 317400.86 | J10: 309269.15 | K10: 292740.65 | L10: 249732.58 | M10: 248742 | N10: 239625 | O10: 211280 | P10: 180794 | Q10: 153958 | S10: 779308 | T10: =(D10*31)/S10 -> 8.1445515 | U10: =RANK(T10,$T$3:$T$53) -> 6
A11: 47 | B11: District of Columbia | D11: 35189.563 | E11: 31825.686 | F11: 31430.327 | G11: 35214 | H11: 26704.4 | I11: 36659 | J11: 33780.1 | K11: 33025.3 | L11: 30201.31 | M11: 29727 | N11: 20660.28 | O11: 14889.25 | P11: 7815 | Q11: 2822 | S11: 526682 | T11: =(D11*31)/S11 -> 2.0712241 | U11: =RANK(T11,$T$3:$T$53) -> 25
A12: 5 | B12: Florida | D12: 1229970 | E12: 1348670.6 | F12: 1281302.2 | G12: 1349261.8 | H12: 1253303 | I12: 1333674.3 | J12: 1374344 | K12: 1408031.8 | L12: 1255111.6 | M12: 1207936 | N12: 1128089 | O12: 129946.33 | P12: 92512 | Q12: 64531 | S12: 17446963 | T12: =(D12*31)/S12 -> 2.1854274 | U12: =RANK(T12,$T$3:$T$53) -> 24
A13: 11 | B13: Georgia | D13: 585428.54 | E13: 495989.94 | F13: 555663.56 | G13: 513445.07 | H13: 504608.55 | I13: 514508.29 | J13: 447095.77 | K13: 408797.72 | L13: 392002.21 | M13: 365015 | N13: 283152.9 | O13: 207256.52 | P13: 153218 | Q13: 129813 | S13: 8037936 | T13: =(D13*31)/S13 -> 2.257829 | U13: =RANK(T13,$T$3:$T$53) -> 22
A14: 29 | B14: Hawaii | D14: 178857.33 | E14: 188348.19 | F14: 185818.68 | G14: 167975 | H14: 59695 | I14: 91756.2 | J14: 77613.5 | K14: 69561.3 | L14: 48638.25 | M14: 40853 | N14: 27759.78 | O14: 25081.82 | P14: 27906 | Q14: 24278 | S14: 1093745 | T14: =(D14*31)/S14 -> 5.0693508 | U14: =RANK(T14,$T$3:$T$53) -> 10
... A40: 7 | B40: Oregon | D40: 1104572.2 | E40: 895741.47 | F40: 960281.09 | G40: 906192.82 | H40: 853404.25 | I40: 1021116.1 | J40: 1021084.7 | K40: 1078391.2 | L40: 1149150.2 | M40: 1081152 | N40: 1039062.8 | O40: 877890.72 | P40: 764226 | Q40: 659598 | S40: 3259500 | T40: =(D40*31)/S40 -> 10.505212 | U40: =RANK(T40,$T$3:$T$53) -> 2
A41: 2 | B41: Pennsylvania | D41: 2654358.6 | E41: 3132799.1 | F41: 3131035.2 | G41: 3244844.1 | H41: 3162473.1 | I41: 3510669.5 | J41: 3705889.7 | K41: 3724010 | L41: 3905620.1 | M41: 4059330 | N41: =4224882.74-150000 -> 4074882.7 | O41: 1788555.9 | P41: 1626116 | Q41: 1547114 | S41: 9803793 | T41: =(D41*31)/S41 -> 8.393192 | U41: =RANK(T41,$T$3:$T$53) -> 5
A42: 42 | B42: Rhode Island | D42: 62483.733 | E42: 92850.627 | F42: 95538.2 | G42: 85307 | H42: 74195.44 | I42: 45392.54 | J42: 47823.97 | K42: 26295 | L42: 27075 | M42: 20807 | N42: 18041.34 | O42: 12217.6 | P42: 7831 | Q42: 7129 | S42: 840348 | T42: =(D42*31)/S42 -> 2.3049924 | U42: =RANK(T42,$T$3:$T$53) -> 21
A43: 35 | B43: South Carolina | D43: 128520.83 | E43: 137968.61 | F43: 139680.21 | G43: 136816.18 | H43: 103107.39 | I43: 108427.38 | J43: 97113.505 | K43: 108210.91 | L43: 101194.38 | M43: 80155 | N43: 56261.25 | O43: 46900.35 | P43: 34496 | Q43: 27501 | S43: 4016679 | T43: =(D43*31)/S43 -> 0.99190046 | U43: =RANK(T43,$T$3:$T$53) -> 43
A44: 48 | B44: South Dakota | D44: 22772.067 | E44: 25623.759 | F44: 26389.24 | G44: 24892.407 | H44: 19903.46 | I44: 20880.24 | J44: 18008.26 | K44: 14057.45 | L44: 10028.81 | M44: 8547 | N44: 4720.5974 | O44: 4008.41 | P44: 3934 | Q44: 3003 | S44: 661415 | T44: =(D44*31)/S44 -> 1.0673089 | U44: =RANK(T44,$T$3:$T$53) -> 41
A45: 25 | B45: Tennessee | D45: 191764.24 | E45: 196516.28 | F45: 204751.11 | G45: 199614 | H45: 170687.76 | I45: 190428.2 | J45: 183808.42 | K45: 253781.75 | L45: 250246.72 | M45: 142818 | N45: 121514.77 | O45: 98507.94 | P45: 54077 | Q45: 33863 | S45: 5301999 | T45: =(D45*31)/S45 -> 1.121217 | U45: =RANK(T45,$T$3:$T$53) -> 40
A46: 4 | B46: Texas | D46: 1368592.6 | E46: 1519691.4 | F46: 1309019.4 | G46: 1269299.1 | H46: 1090563.5 | I46: 1190504.5 | J46: 1153817.5 | K46: 1156535.6 | L46: 1165579 | M46: 1135043 | N46: 982917.89 | O46: 848258.81 | P46: 713712 | Q46: 624903 | S46: 21706890 | T46: =(D46*31)/S46 -> 1.9545117 | U46: =RANK(T46,$T$3:$T$53) -> 27
A47: 34 | B47: Utah | D47: 128672.7 | E47: 141226.73 | F47: 153698.16 | G47: 158736.36 | H47: 156936.26 | I47: 191638.55 | J47: 193029.68 | K47: 206529.43 | L47: 199220.14 | M47: 183660 | N47: 161606.25 | O47: 130789.93 | P47: 110025 | Q47: 86198 | S47: 2323601 | T47: =(D47*31)/S47 -> 1.716669 | U47: =RANK(T47,$T$3:$T$53) -> 30
A48: 18 | B48: Vermont | D48: 353032.09 | E48: 352998.56 | F48: 330202.67 | G48: 312186.3 | H48: 347114.69 | I48: 345307.41 | J48: 333827.4 | K48: 292478.93 | L48: 295716.57 | M48: 261654 | N48: 243905.14 | O48: 229061.69 | P48: 204693 | Q48: 199830 | S48: 501345 | T48: =(D48*31)/S48 -> 21.829269 | U48: =RANK(T48,$T$3:$T$53) -> 1
A49: 16 | B49: Virginia | D49: 397160.93 | E49: 357390.48 | F49: 360074.75 | G49: 454011.28 | H49: 391605.11 | I49: 352356.82 | J49: 312593.48 | K49: 358903.2 | L49: 257644.62 | M49: 274111 | N49: 195956.64 | O49: 129102.63 | P49: 84059 | Q49: 61440 | S49: 6493085 | T49: =(D49*31)/S49 -> 1.8961694 | U49: =RANK(T49,$T$3:$T$53) -> 28
A50: 12 | B50: Washington | D50: 528013.32 | E50: 560966.82 | F50: 581072.3 | G50: 567733.15 | H50: 487819.55 | I50: 598350.57 | J50: 570352.83 | K50: 510681.58 | L50: 467269.54 | M50: 426462 | N50: 405130.93 | O50: 333174.59 | P50: 291107 | Q50: 235532 | S50: 5897062 | T50: =(D50*31)/S50 -> 2.7756895 | U50: =RANK(T50,$T$3:$T$53) -> 20
A51: 49 | B51: West Virginia | D51: 21618.839 | E51: 23912.729 | F51: 23837.126 | G51: 23674 | H51: 22229.76 | I51: 23006.34 | J51: 18566.17 | K51: 12988.98 | L51: 14681.86 | M51: 14161 | N51: 7923.31 | O51: =5147 -> 5147 | P51: 3752 | Q51: 3055 | S51: 1345507 | T51: =(D51*31)/S51 -> 0.49809031 | U51: =RANK(T51,$T$3:$T$53) -> 50
A52: 10 | B52: Wisconsin | D52: 742240.25 | E52: 771252.13 | F52: 859129.69 | G52: 984886.61 | H52: 758972.96 | I52: 819685.94 | J52: 867663.48 | K52: 1029915.9 | L52: 974537.53 | M52: 1020567 | N52: 850874.12 | O52: 458706.12 | P52: 398811 | Q52: 388025 | S52: 4432759 | T52: =(D52*31)/S52 -> 5.1907735 | U52: =RANK(T52,$T$3:$T$53) -> 9
A53: 41 | B53: Wyoming | D53: 68406.99 | E53: 64116.689 | F53: 66070.566 | G53: 64559 | H53: 58590.44 | I53: 59169.33 | J53: 52787.48 | K53: 45400.76 | L53: 31356.81 | M53: 21053 | N53: 18616.59 | O53: 15863 | P53: 14070 | Q53: 10607 | S53: 431053 | T53: =(D53*31)/S53 -> 4.9196194 | U53: =RANK(T53,$T$3:$T$53) -> 11
B55: Total | D55: =SUM(D3:D54) -> 23103885 | E55: =SUM(E3:E54) -> 23357835 | F55: =SUM(F3:F54) -> 23547421 | G55: =SUM(G3:G54) -> 24725270 | H55: =SUM(H3:H54) -> 22817184 | I55: =SUM(I3:I54) -> 26334229 | J55: =SUM(J3:J54) -> 25519455 | K55: =SUM(K3:K54) -> 25280679 | L55: 24570644 | M55: 24523015 | N55: 22099388 | O55: 15579181 | P55: 13235917 | Q55: 11458152 | S55: =SUM(S3:S53) -> 249124385 | T55: =(D55*31)/S55 -> 2.8749512
A56: NOTE: when known, contract production applied to state where the brewing happened; Does not include overseas production where able to separate.
A57: Historical state data may not always be comparable due to definition and data set changes. In 2022 this is most notable for Michigan production.

Sheet 6. Breweries by State
A1: State | B1: Abbrev. | D1: 21 + Population | F1: Craft Breweries | G1: Rank | H1: Craft Breweries/ 100,000 21+ Adults | I1: Craft Breweries/ Capita Rank | K1: Total Breweries | L1: Rank | M1: Total Breweries/ 100,000 21+ Adults | N1: Total Breweries/ Capita Rank
A2: Alabama | B2: AL | D2: ='5. State Production'!S3 -> 3763934 | F2: 53 | G2: =RANK(F2,$F$2:$F$53) -> 39 | H2: =F2/(D2/100000) -> 1.4081012 | I2: =RANK(H2,$H$2:$H$53) -> 50 | K2: 53 | L2: =RANK(K2,$K$2:$K$53) -> 39 | M2: =K2/(D2/100000) -> 1.4081012 | N2: =RANK(M2,$M$2:$M$53) -> 50
A3: Alaska | B3: AK | D3: ='5. State Production'!S4 -> 533123 | F3: 61 | G3: =RANK(F3,$F$2:$F$53) -> 37 | H3: =F3/(D3/100000) -> 11.442012 | I3: =RANK(H3,$H$2:$H$53) -> 5 | K3: 61 | L3: =RANK(K3,$K$2:$K$53) -> 37 | M3: =K3/(D3/100000) -> 11.442012 | N3: =RANK(M3,$M$2:$M$53) -> 5
A4: Arizona | B4: AZ | D4: ='5. State Production'!S5 -> 5553078 | F4: 127 | G4: =RANK(F4,$F$2:$F$53) -> 25 | H4: =F4/(D4/100000) -> 2.2870199 | I4: =RANK(H4,$H$2:$H$53) -> 44 | K4: 129 | L4: =RANK(K4,$K$2:$K$53) -> 25 | M4: =K4/(D4/100000) -> 2.323036 | N4: =RANK(M4,$M$2:$M$53) -> 44
A5: Arkansas | B5: AR | D5: ='5. State Production'!S6 -> 2243142 | F5: 58 | G5: =RANK(F5,$F$2:$F$53) -> 38 | H5: =F5/(D5/100000) -> 2.5856589 | I5: =RANK(H5,$H$2:$H$53) -> 40 | K5: 58 | L5: =RANK(K5,$K$2:$K$53) -> 38 | M5: =K5/(D5/100000) -> 2.5856589 | N5: =RANK(M5,$M$2:$M$53) -> 40
A6: California | B6: CA | D6: ='5. State Production'!S7 -> 28988643 | F6: 946 | G6: =RANK(F6,$F$2:$F$53) -> 1 | H6: =F6/(D6/100000) -> 3.263347 | I6: =RANK(H6,$H$2:$H$53) -> 31 | K6: 956 | L6: =RANK(K6,$K$2:$K$53) -> 1 | M6: =K6/(D6/100000) -> 3.2978432 | N6: =RANK(M6,$M$2:$M$53) -> 31
A7: Colorado | B7: CO | D7: ='5. State Production'!S8 -> 4441305 | F7: 456 | G7: =RANK(F7,$F$2:$F$53) -> 4 | H7: =F7/(D7/100000) -> 10.267253 | I7: =RANK(H7,$H$2:$H$53) -> 6 | K7: 460 | L7: =RANK(K7,$K$2:$K$53) -> 4 | M7: =K7/(D7/100000) -> 10.357316 | N7: =RANK(M7,$M$2:$M$53) -> 6
A8: Connecticut | B8: CT | D8: ='5. State Production'!S9 -> 2743788 | F8: 122 | G8: =RANK(F8,$F$2:$F$53) -> 27 | H8: =F8/(D8/100000) -> 4.4464077 | I8: =RANK(H8,$H$2:$H$53) -> 24 | K8: 122 | L8: =RANK(K8,$K$2:$K$53) -> 27 | M8: =K8/(D8/100000) -> 4.4464077 | N8: =RANK(M8,$M$2:$M$53) -> 24
A9: Delaware | B9: DE | D9: ='5. State Production'!S10 -> 779308 | F9: 38 | G9: =RANK(F9,$F$2:$F$53) -> 46 | H9: =F9/(D9/100000) -> 4.8761209 | I9: =RANK(H9,$H$2:$H$53) -> 22 | K9: 38 | L9: =RANK(K9,$K$2:$K$53) -> 46 | M9: =K9/(D9/100000) -> 4.8761209 | N9: =RANK(M9,$M$2:$M$53) -> 22
A10: District of Columbia | B10: DC | D10: ='5. State Production'!S11 -> 526682 | F10: 14 | G10: =RANK(F10,$F$2:$F$53) -> 51 | H10: =F10/(D10/100000) -> 2.6581505 | I10: =RANK(H10,$H$2:$H$53) -> 39 | K10: 14 | L10: =RANK(K10,$K$2:$K$53) -> 51 | M10: =K10/(D10/100000) -> 2.6581505 | N10: =RANK(M10,$M$2:$M$53) -> 39
A11: Florida | B11: FL | D11: ='5. State Production'!S12 -> 17446963 | F11: 391 | G11: =RANK(F11,$F$2:$F$53) -> 10 | H11: =F11/(D11/100000) -> 2.2410777 | I11: =RANK(H11,$H$2:$H$53) -> 45 | K11: 395 | L11: =RANK(K11,$K$2:$K$53) -> 10 | M11: =K11/(D11/100000) -> 2.2640043 | N11: =RANK(M11,$M$2:$M$53) -> 45
A12: Georgia | B12: GA | D12: ='5. State Production'!S13 -> 8037936 | F12: 190 | G12: =RANK(F12,$F$2:$F$53) -> 18 | H12: =F12/(D12/100000) -> 2.3637909 | I12: =RANK(H12,$H$2:$H$53) -> 43 | K12: 192 | L12: =RANK(K12,$K$2:$K$53) -> 18 | M12: =K12/(D12/100000) -> 2.3886729 | N12: =RANK(M12,$M$2:$M$53) -> 42
A13: Hawaii | B13: HI | D13: ='5. State Production'!S14 -> 1093745 | F13: 26 | G13: =RANK(F13,$F$2:$F$53) -> 48 | H13: =F13/(D13/100000) -> 2.3771537 | I13: =RANK(H13,$H$2:$H$53) -> 42 | K13: 26 | L13: =RANK(K13,$K$2:$K$53) -> 48 | M13: =K13/(D13/100000) -> 2.3771537 | N13: =RANK(M13,$M$2:$M$53) -> 43
... A40: Pennsylvania | B40: PA | D40: ='5. State Production'!S41 -> 9803793 | F40: 533 | G40: =RANK(F40,$F$2:$F$53) -> 3 | H40: =F40/(D40/100000) -> 5.4366713 | I40: =RANK(H40,$H$2:$H$53) -> 16 | K40: 533 | L40: =RANK(K40,$K$2:$K$53) -> 3 | M40: =K40/(D40/100000) -> 5.4366713 | N40: =RANK(M40,$M$2:$M$53) -> 16
A41: Puerto Rico | B41: PR | D41: 2584911 | F41: 8 | G41: =RANK(F41,$F$2:$F$53) -> 52 | H41: =F41/(D41/100000) -> 0.30948841 | I41: =RANK(H41,$H$2:$H$53) -> 52 | K41: 8 | L41: =RANK(K41,$K$2:$K$53) -> 52 | M41: =K41/(D41/100000) -> 0.30948841 | N41: =RANK(M41,$M$2:$M$53) -> 52
A42: Rhode Island | B42: RI | D42: ='5. State Production'!S42 -> 840348 | F42: 42 | G42: =RANK(F42,$F$2:$F$53) -> 45 | H42: =F42/(D42/100000) -> 4.9979294 | I42: =RANK(H42,$H$2:$H$53) -> 20 | K42: 42 | L42: =RANK(K42,$K$2:$K$53) -> 45 | M42: =K42/(D42/100000) -> 4.9979294 | N42: =RANK(M42,$M$2:$M$53) -> 20
A43: South Carolina | B43: SC | D43: ='5. State Production'!S43 -> 4016679 | F43: 131 | G43: =RANK(F43,$F$2:$F$53) -> 24 | H43: =F43/(D43/100000) -> 3.2614008 | I43: =RANK(H43,$H$2:$H$53) -> 32 | K43: 131 | L43: =RANK(K43,$K$2:$K$53) -> 24 | M43: =K43/(D43/100000) -> 3.2614008 | N43: =RANK(M43,$M$2:$M$53) -> 32
A44: South Dakota | B44: SD | D44: ='5. State Production'!S44 -> 661415 | F44: 44 | G44: =RANK(F44,$F$2:$F$53) -> 44 | H44: =F44/(D44/100000) -> 6.6524043 | I44: =RANK(H44,$H$2:$H$53) -> 12 | K44: 44 | L44: =RANK(K44,$K$2:$K$53) -> 44 | M44: =K44/(D44/100000) -> 6.6524043 | N44: =RANK(M44,$M$2:$M$53) -> 12
A45: Tennessee | B45: TN | D45: ='5. State Production'!S45 -> 5301999 | F45: 157 | G45: =RANK(F45,$F$2:$F$53) -> 22 | H45: =F45/(D45/100000) -> 2.9611473 | I45: =RANK(H45,$H$2:$H$53) -> 35 | K45: 157 | L45: =RANK(K45,$K$2:$K$53) -> 22 | M45: =K45/(D45/100000) -> 2.9611473 | N45: =RANK(M45,$M$2:$M$53) -> 35
A46: Texas | B46: TX | D46: ='5. State Production'!S46 -> 21706890 | F46: 440 | G46: =RANK(F46,$F$2:$F$53) -> 6 | H46: =F46/(D46/100000) -> 2.0270062 | I46: =RANK(H46,$H$2:$H$53) -> 48 | K46: 445 | L46: =RANK(K46,$K$2:$K$53) -> 6 | M46: =K46/(D46/100000) -> 2.0500403 | N46: =RANK(M46,$M$2:$M$53) -> 48
A47: Utah | B47: UT | D47: ='5. State Production'!S47 -> 2323601 | F47: 48 | G47: =RANK(F47,$F$2:$F$53) -> 43 | H47: =F47/(D47/100000) -> 2.0657591 | I47: =RANK(H47,$H$2:$H$53) -> 47 | K47: 48 | L47: =RANK(K47,$K$2:$K$53) -> 43 | M47: =K47/(D47/100000) -> 2.0657591 | N47: =RANK(M47,$M$2:$M$53) -> 47
A48: Vermont | B48: VT | D48: ='5. State Production'!S48 -> 501345 | F48: 77 | G48: =RANK(F48,$F$2:$F$53) -> 35 | H48: =F48/(D48/100000) -> 15.358685 | I48: =RANK(H48,$H$2:$H$53) -> 1 | K48: 77 | L48: =RANK(K48,$K$2:$K$53) -> 35 | M48: =K48/(D48/100000) -> 15.358685 | N48: =RANK(M48,$M$2:$M$53) -> 1
A49: Virginia | B49: VA | D49: ='5. State Production'!S49 -> 6493085 | F49: 345 | G49: =RANK(F49,$F$2:$F$53) -> 11 | H49: =F49/(D49/100000) -> 5.3133449 | I49: =RANK(H49,$H$2:$H$53) -> 19 | K49: 352 | L49: =RANK(K49,$K$2:$K$53) -> 11 | M49: =K49/(D49/100000) -> 5.4211519 | N49: =RANK(M49,$M$2:$M$53) -> 18
A50: Washington | B50: WA | D50: ='5. State Production'!S50 -> 5897062 | F50: 444 | G50: =RANK(F50,$F$2:$F$53) -> 5 | H50: =F50/(D50/100000) -> 7.529173 | I50: =RANK(H50,$H$2:$H$53) -> 9 | K50: 448 | L50: =RANK(K50,$K$2:$K$53) -> 5 | M50: =K50/(D50/100000) -> 7.5970034 | N50: =RANK(M50,$M$2:$M$53) -> 9
A51: West Virginia | B51: WV | D51: ='5. State Production'!S51 -> 1345507 | F51: 36 | G51: =RANK(F51,$F$2:$F$53) -> 47 | H51: =F51/(D51/100000) -> 2.6755714 | I51: =RANK(H51,$H$2:$H$53) -> 38 | K51: 36 | L51: =RANK(K51,$K$2:$K$53) -> 47 | M51: =K51/(D51/100000) -> 2.6755714 | N51: =RANK(M51,$M$2:$M$53) -> 38
A52: Wisconsin | B52: WI | D52: ='5. State Production'!S52 -> 4432759 | F52: 262 | G52: =RANK(F52,$F$2:$F$53) -> 14 | H52: =F52/(D52/100000) -> 5.9105401 | I52: =RANK(H52,$H$2:$H$53) -> 13 | K52: 266 | L52: =RANK(K52,$K$2:$K$53) -> 14 | M52: =K52/(D52/100000) -> 6.0007774 | N52: =RANK(M52,$M$2:$M$53) -> 13
A53: Wyoming | B53: WY | D53: ='5. State Production'!S53 -> 431053 | F53: 51 | G53: =RANK(F53,$F$2:$F$53) -> 41 | H53: =F53/(D53/100000) -> 11.831492 | I53: =RANK(H53,$H$2:$H$53) -> 4 | K53: 51 | L53: =RANK(K53,$K$2:$K$53) -> 41 | M53: =K53/(D53/100000) -> 11.831492 | N53: =RANK(M53,$M$2:$M$53) -> 4
A55: Total | D55: =SUM(D2:D53) -> 251709296 | F55: =SUM(F2:F53) -> 9843 | H55: =F55/(D55/100000) -> 3.9104634 | K55: =SUM(K2:K53) -> 9904 | M55: =K55/(D55/100000) -> 3.9346977

Sheet 7. 21+ Population Data
A1: State | B1: Abbrev. | C1: Population (2024) | D1: 21+ Ratio | E1: 21+ Adults
A2: Alabama | B2: AL | C2: 5157699 | D2: =E2/C2 -> 0.72977 | E2: =INDEX('6. Breweries by State'!$D$2:$D$53,MATCH($A2,'6. Breweries by State'!$A$2:$A$53,0)) -> 3763934
A3: Alaska | B3: AK | C3: 740133 | D3: =E3/C3 -> 0.72030703 | E3: =INDEX('6. Breweries by State'!$D$2:$D$53,MATCH($A3,'6. Breweries by State'!$A$2:$A$53,0)) -> 533123
A4: Arizona | B4: AZ | C4: 7582384 | D4: =E4/C4 -> 0.7323657 | E4: =INDEX('6. Breweries by State'!$D$2:$D$53,MATCH($A4,'6. Breweries by State'!$A$2:$A$53,0)) -> 5553078
A5: Arkansas | B5: AR | C5: 3088354 | D5: =E5/C5 -> 0.72632282 | E5: =INDEX('6. Breweries by State'!$D$2:$D$53,MATCH($A5,'6. Breweries by State'!$A$2:$A$53,0)) -> 2243142
A6: California | B6: CA | C6: 39431263 | D6: =E6/C6 -> 0.73516902 | E6: =INDEX('6. Breweries by State'!$D$2:$D$53,MATCH($A6,'6. Breweries by State'!$A$2:$A$53,0)) -> 28988643
A7: Colorado | B7: CO | C7: 5957493 | D7: =E7/C7 -> 0.74549899 | E7: =INDEX('6. Breweries by State'!$D$2:$D$53,MATCH($A7,'6. Breweries by State'!$A$2:$A$53,0)) -> 4441305
A8: Connecticut | B8: CT | C8: 3675069 | D8: =E8/C8 -> 0.74659496 | E8: =INDEX('6. Breweries by State'!$D$2:$D$53,MATCH($A8,'6. Breweries by State'!$A$2:$A$53,0)) -> 2743788
A9: Delaware | B9: DE | C9: 1051917 | D9: =E9/C9 -> 0.74084552 | E9: =INDEX('6. Breweries by State'!$D$2:$D$53,MATCH($A9,'6. Breweries by State'!$A$2:$A$53,0)) -> 779308
A10: District of Columbia | B10: DC | C10: 702250 | D10: =E10/C10 -> 0.74999217 | E10: =INDEX('6. Breweries by State'!$D$2:$D$53,MATCH($A10,'6. Breweries by State'!$A$2:$A$53,0)) -> 526682
A11: Florida | B11: FL | C11: 23372215 | D11: =E11/C11 -> 0.74648308 | E11: =INDEX('6. Breweries by State'!$D$2:$D$53,MATCH($A11,'6. Breweries by State'!$A$2:$A$53,0)) -> 17446963
A12: Georgia | B12: GA | C12: 11180878 | D12: =E12/C12 -> 0.71890025 | E12: =INDEX('6. Breweries by State'!$D$2:$D$53,MATCH($A12,'6. Breweries by State'!$A$2:$A$53,0)) -> 8037936
A13: Hawaii | B13: HI | C13: 1446146 | D13: =E13/C13 -> 0.75631714 | E13: =INDEX('6. Breweries by State'!$D$2:$D$53,MATCH($A13,'6. Breweries by State'!$A$2:$A$53,0)) -> 1093745
... A53: Wyoming | B53: WY | C53: 587618 | D53: =E53/C53 -> 0.7335599 | E53: =INDEX('6. Breweries by State'!$D$2:$D$53,MATCH($A53,'6. Breweries by State'!$A$2:$A$53,0)) -> 431053
A55: Total | C55: =SUM(C2:C53) -> 343314283 | D55: =E55/C55 -> 0.73317455 | E55: =SUM(E2:E53) -> 251709296
A56: Source: U.S. Census Bureau. State population numbers from v2024 data (NST-EST2024-POP). Since no 2024 state level single age population tables exist yet, 21+ population and percentage uses 2022 21+ state percentages.

Sheet 8. TTB State Permit Data
C1: BREWERY COUNT BY STATE: 2000 - 2024
C2: Count reflects active TTB licenses and does not reflect active breweries selling in the marketplace
C3: Does not include Territories of the United States
C4: 2000 | D4: 2001 | E4: 2002 | F4: 2003 | G4: 2004 | H4: 2005 | I4: 2006 | J4: 2007 | K4: 2008 | L4: 2009 | M4: 2010 | N4: 2011 | O4: 2012 | P4: 2013 | Q4: 2014 | R4: 2015 | S4: 2016 | T4: 2017 | U4: 2018 | V4: 2019 | W4: 2020 | X4: 2021 | Y4: 2022 | Z4: 2023 | AA4: 2024
A5: STATE | B5: Abbrev. | C5: COUNT | D5: COUNT | E5: COUNT | F5: COUNT | G5: COUNT | H5: COUNT | I5: COUNT | J5: COUNT | K5: COUNT | L5: COUNT | M5: COUNT | N5: COUNT | O5: COUNT | P5: COUNT | Q5: COUNT | R5: COUNT | S5: COUNT | T5: COUNT | U5: COUNT | V5: COUNT | W5: COUNT | X5: COUNT | Y5: COUNT | Z5: COUNT | AA5: COUNT
A6: Alabama | B6: AL | C6: 7 | D6: 4 | E6: 3 | F6: 3 | G6: 5 | H6: 5 | I6: 4 | J6: 5 | K6: 5 | L6: 5 | M6: 7 | N6: 9 | O6: 15 | P6: 23 | Q6: 25 | R6: 30 | S6: 37 | T6: 52 | U6: 55 | V6: 66 | W6: 68 | X6: 77 | Y6: 84 | Z6: 93 | AA6: 99
A7: Alaska | B7: AK | C7: 17 | D7: 17 | E7: 19 | F7: 15 | G7: 13 | H7: 15 | I7: 14 | J7: 15 | K7: 16 | L7: 18 | M7: 20 | N7: 23 | O7: 25 | P7: 25 | Q7: 28 | R7: 35 | S7: 36 | T7: 45 | U7: 51 | V7: 59 | W7: 66 | X7: 72 | Y7: 75 | Z7: 79 | AA7: 80
A8: Arizona | B8: AZ | C8: 45 | D8: 45 | E8: 39 | F8: 36 | G8: 31 | H8: 31 | I8: 33 | J8: 33 | K8: 33 | L8: 34 | M8: 37 | N8: 45 | O8: 55 | P8: 59 | Q8: 77 | R8: 91 | S8: 110 | T8: 130 | U8: 146 | V8: 157 | W8: 170 | X8: 179 | Y8: 184 | Z8: 186 | AA8: 197
A9: Arkansas | B9: AR | C9: 5 | D9: 5 | E9: 4 | F9: 4 | G9: 4 | H9: 4 | I9: 4 | J9: 4 | K9: 4 | L9: 5 | M9: 5 | N9: 7 | O9: 13 | P9: 18 | Q9: 23 | R9: 29 | S9: 34 | T9: 44 | U9: 53 | V9: 58 | W9: 70 | X9: 76 | Y9: 82 | Z9: 90 | AA9: 94
A10: California | B10: CA | C10: 281 | D10: 266 | E10: 270 | F10: 278 | G10: 282 | H10: 278 | I10: 293 | J10: 310 | K10: 333 | L10: 340 | M10: 358 | N10: 401 | O10: 472 | P10: 528 | Q10: 654 | R10: 788 | S10: 927 | T10: 1106 | U10: 1236 | V10: 1370 | W10: 1465 | X10: 1524 | Y10: 1571 | Z10: 1563 | AA10: 1624
A11: Colorado | B11: CO | C11: 102 | D11: 102 | E11: 102 | F11: 99 | G11: 99 | H11: 104 | I11: 102 | J11: 112 | K11: 117 | L11: 116 | M11: 129 | N11: 149 | O11: 185 | P11: 234 | Q11: 300 | R11: 352 | S11: 386 | T11: 448 | U11: 500 | V11: 544 | W11: 561 | X11: 586 | Y11: 614 | Z11: 619 | AA11: 641
A12: Connecticut | B12: CT | C12: 27 | D12: 22 | E12: 17 | F12: 17 | G12: 20 | H12: 19 | I12: 18 | J12: 19 | K12: 21 | L12: 19 | M12: 21 | N12: 20 | O12: 24 | P12: 39 | Q12: 50 | R12: 59 | S12: 76 | T12: 103 | U12: 124 | V12: 149 | W12: 162 | X12: 172 | Y12: 176 | Z12: 177 | AA12: 179
A13: Delaware | B13: DE | C13: 8 | D13: 8 | E13: 8 | F13: 9 | G13: 9 | H13: 8 | I13: 9 | J13: 10 | K13: 9 | L13: 11 | M13: 11 | N13: 12 | O13: 13 | P13: 13 | Q13: 15 | R13: 21 | S13: 25 | T13: 33 | U13: 38 | V13: 43 | W13: 47 | X13: 51 | Y13: 54 | Z13: 57 | AA13: 60
A14: District of Columbia | B14: DC | C14: 4 | D14: 5 | E14: 5 | F14: 4 | G14: 5 | H14: 4 | I14: 4 | J14: 3 | K14: 3 | L14: 3 | M14: 4 | N14: 6 | O14: 5 | P14: 11 | Q14: 12 | R14: 13 | S14: 13 | T14: 13 | U14: 13 | V14: 15 | W14: 17 | X14: 19 | Y14: 21 | Z14: 21 | AA14: 22
A15: Florida | B15: FL | C15: 92 | D15: 84 | E15: 83 | F15: 78 | G15: 74 | H15: 69 | I15: 51 | J15: 50 | K15: 61 | L15: 52 | M15: 60 | N15: 71 | O15: 89 | P15: 113 | Q15: 158 | R15: 205 | S15: 264 | T15: 338 | U15: 386 | V15: 464 | W15: 500 | X15: 531 | Y15: 571 | Z15: 598 | AA15: 618
A16: Georgia | B16: GA | C16: 29 | D16: 30 | E16: 25 | F16: 29 | G16: 29 | H16: 25 | I16: 22 | J16: 23 | K16: 20 | L16: 22 | M16: 26 | N16: 25 | O16: 31 | P16: 37 | Q16: 48 | R16: 54 | S16: 69 | T16: 102 | U16: 121 | V16: 158 | W16: 186 | X16: 208 | Y16: 234 | Z16: 244 | AA16: 265
A17: Hawaii | B17: HI | C17: 15 | D17: 14 | E17: 13 | F17: 13 | G17: 13 | H17: 12 | I17: 12 | J17: 12 | K17: 11 | L17: 11 | M17: 11 | N17: 12 | O17: 15 | P17: 17 | Q17: 20 | R17: 26 | S17: 23 | T17: 28 | U17: 38 | V17: 43 | W17: 44 | X17: 50 | Y17: 52 | Z17: 52 | AA17: 53
... A29: Minnesota | B29: MN | C29: 41 | D29: 37 | E29: 37 | F29: 31 | G29: 30 | H29: 31 | I29: 35 | J29: 34 | K29: 36 | L29: 39 | M29: 42 | N29: 56 | O29: 70 | P29: 75 | Q29: 113 | R29: 142 | S29: 165 | T29: 214 | U29: 239 | V29: 267 | W29: 286 | X29: 301 | Y29: 314 | Z29: 322 | AA29: 331
A30: Mississippi | B30: MS | C30: 4 | D30: 4 | E30: 4 | F30: 3 | G30: 3 | H30: 3 | I30: * | J30: * | K30: * | L30: * | M30: 3 | N30: * | O30: 4 | P30: 7 | Q30: 10 | R30: 14 | S30: 14 | T30: 16 | U30: 19 | V30: 22 | W30: 25 | X30: 32 | Y30: 33 | Z30: 35 | AA30: 38
A31: Missouri | B31: MO | C31: 32 | D31: 26 | E31: 28 | F31: 28 | G31: 28 | H31: 33 | I31: 34 | J31: 38 | K31: 38 | L31: 47 | M31: 51 | N31: 55 | O31: 60 | P31: 63 | Q31: 77 | R31: 90 | S31: 116 | T31: 145 | U31: 168 | V31: 192 | W31: 212 | X31: 230 | Y31: 249 | Z31: 261 | AA31: 275
A32: Montana | B32: MT | C32: 25 | D32: 26 | E32: 28 | F32: 24 | G32: 22 | H32: 21 | I32: 22 | J32: 26 | K32: 31 | L32: 31 | M32: 31 | N32: 35 | O32: 41 | P32: 49 | Q32: 62 | R32: 74 | S32: 79 | T32: 98 | U32: 108 | V32: 121 | W32: 128 | X32: 137 | Y32: 139 | Z32: 138 | AA32: 142
A33: Nebraska | B33: NE | C33: 9 | D33: 11 | E33: 10 | F33: 12 | G33: 12 | H33: 16 | I33: 16 | J33: 17 | K33: 16 | L33: 17 | M33: 16 | N33: 18 | O33: 20 | P33: 25 | Q33: 35 | R33: 39 | S33: 47 | T33: 53 | U33: 60 | V33: 67 | W33: 73 | X33: 78 | Y33: 82 | Z33: 81 | AA33: 87
A34: Nevada | B34: NV | C34: 22 | D34: 16 | E34: 17 | F34: 16 | G34: 17 | H34: 16 | I34: 16 | J34: 16 | K34: 17 | L34: 18 | M34: 20 | N34: 20 | O34: 23 | P34: 26 | Q34: 34 | R34: 39 | S34: 44 | T34: 46 | U34: 50 | V34: 65 | W34: 71 | X34: 73 | Y34: 72 | Z34: 76 | AA34: 81
A35: New Hampshire | B35: NH | C35: 19 | D35: 17 | E35: 17 | F35: 16 | G35: 16 | H35: 14 | I35: 14 | J35: 15 | K35: 16 | L35: 17 | M35: 19 | N35: 21 | O35: 25 | P35: 35 | Q35: 46 | R35: 63 | S35: 73 | T35: 88 | U35: 106 | V35: 125 | W35: 135 | X35: 140 | Y35: 156 | Z35: 154 | AA35: 161
A36: New Jersey | B36: NJ | C36: 24 | D36: 22 | E36: 20 | F36: 22 | G36: 21 | H36: 21 | I36: 21 | J36: 21 | K36: 20 | L36: 22 | M36: 24 | N36: 31 | O36: 29 | P36: 37 | Q36: 49 | R36: 71 | S36: 96 | T36: 123 | U36: 146 | V36: 175 | W36: 186 | X36: 198 | Y36: 211 | Z36: 219 | AA36: 232
A37: New Mexico | B37: NM | C37: 26 | D37: 23 | E37: 23 | F37: 20 | G37: 22 | H37: 22 | I37: 23 | J37: 21 | K37: 20 | L37: 21 | M37: 26 | N37: 30 | O37: 38 | P37: 48 | Q37: 60 | R37: 71 | S37: 86 | T37: 110 | U37: 124 | V37: 143 | W37: 151 | X37: 155 | Y37: 161 | Z37: 159 | AA37: 169
A38: New York | B38: NY | C38: 78 | D38: 83 | E38: 84 | F38: 86 | G38: 80 | H38: 82 | I38: 82 | J38: 77 | K38: 81 | L38: 84 | M38: 100 | N38: 123 | O38: 150 | P38: 193 | Q38: 255 | R38: 329 | S38: 394 | T38: 471 | U38: 532 | V38: 618 | W38: 666 | X38: 720 | Y38: 762 | Z38: 788 | AA38: 822
A39: North Carolina | B39: NC | C39: 51 | D39: 38 | E39: 38 | F39: 41 | G39: 43 | H39: 45 | I39: 46 | J39: 45 | K39: 50 | L39: 52 | M39: 61 | N39: 71 | O39: 94 | P39: 125 | Q39: 155 | R39: 207 | S39: 260 | T39: 330 | U39: 387 | V39: 443 | W39: 491 | X39: 544 | Y39: 578 | Z39: 597 | AA39: 613
A40: North Dakota | B40: ND | C40: 3 | D40: 3 | E40: 3 | F40: 3 | G40: 4 | H40: 4 | I40: 3 | J40: 3 | K40: 3 | L40: 3 | M40: 3 | N40: 3 | O40: 7 | P40: 8 | Q40: 10 | R40: 11 | S40: 15 | T40: 22 | U40: 26 | V40: 29 | W40: 31 | X40: 34 | Y40: 33 | Z40: 33 | AA40: 33
A41: Ohio | B41: OH | C41: 87 | D41: 74 | E41: 64 | F41: 59 | G41: 55 | H41: 53 | I41: 57 | J41: 58 | K41: 66 | L41: 66 | M41: 75 | N41: 81 | O41: 99 | P41: 114 | Q41: 151 | R41: 187 | S41: 236 | T41: 324 | U41: 377 | V41: 437 | W41: 482 | X41: 525 | Y41: 563 | Z41: 602 | AA41: 625
A42: Oklahoma | B42: OK | C42: 9 | D42: 6 | E42: 6 | F42: 6 | G42: 7 | H42: 8 | I42: 7 | J42: 6 | K42: 9 | L42: 10 | M42: 10 | N42: 10 | O42: 13 | P42: 17 | Q42: 18 | R42: 21 | S42: 26 | T42: 43 | U42: 55 | V42: 76 | W42: 88 | X42: 95 | Y42: 102 | Z42: 108 | AA42: 114
... A56: Wyoming | B56: WY | C56: 13 | D56: 11 | E56: 11 | F56: 11 | G56: 13 | H56: 14 | I56: 14 | J56: 14 | K56: 14 | L56: 13 | M56: 16 | N56: 15 | O56: 19 | P56: 25 | Q56: 28 | R56: 32 | S56: 33 | T56: 39 | U56: 44 | V56: 51 | W56: 51 | X56: 56 | Y56: 59 | Z56: 61 | AA56: 64
I57: 2 | J57: 2 | K57: 1 | L57: 2 | N57: 2
A58: Total | C58: =SUM(C6:C56) -> 1964 | D58: =SUM(D6:D56) -> 1817 | E58: =SUM(E6:E56) -> 1794 | F58: =SUM(F6:F56) -> 1791 | G58: =SUM(G6:G56) -> 1832 | H58: =SUM(H6:H56) -> 1821 | I58: =SUM(I6:I56) -> 1865 | J58: =SUM(J6:J56) -> 1933 | ... Z58: =SUM(Z6:Z56) -> 14597

Sheet 9. Do Not Publish List
A1: This list of breweries is a compilation of breweries that provided data and selected "do not publish" as well as breweries that previously selected that option, didn't respond, and had 2024 estimates based off those "do not publish" responses.
A5: 1905 Brewing Company
A6: 2 Way Brewing Company
A7: 300 Suns Brewing
A8: 3rd Turn Brewing
A9: 603 Brewery
A10: 60cc Brewing
A11: 7 Dogs Brewpub
A12: A Homestead Brew
A13: Abandon Brewing Company
A14: Accomplice Beer Company
A15: Acorn Brewing
... A483: Yard Goat Artisan Ales LLC
